[32m2024-07-09 15:42:46 -0400[0m - dagster - [34mDEBUG[0m - __ASSET_JOB - 01bac1b4-99de-45e5-8086-b97dff3a9c37 - 6234 - LOGS_CAPTURED - Started capturing logs in process (pid: 6234).
[32m2024-07-09 15:42:46 -0400[0m - dagster - [34mDEBUG[0m - __ASSET_JOB - 01bac1b4-99de-45e5-8086-b97dff3a9c37 - 6234 - SET_FMC_MTD_FL_INIT_SLS - STEP_START - Started execution of step "SET_FMC_MTD_FL_INIT_SLS".
[32m2024-07-09 15:42:46 -0400[0m - dagster - [34mINFO[0m - __ASSET_JOB - 01bac1b4-99de-45e5-8086-b97dff3a9c37 - SET_FMC_MTD_FL_INIT_SLS - Executing query: 
        CALL SPEEDSHOP_PROC.SET_FMC_MTD_FL_INIT_SLS('{dag_name}', '{load_cycle_id}', '{load_timestamp}');
    
[32m2024-07-09 15:42:47 -0400[0m - dagster - [34mERROR[0m - [31m__ASSET_JOB - 01bac1b4-99de-45e5-8086-b97dff3a9c37 - 6234 - SET_FMC_MTD_FL_INIT_SLS - STEP_FAILURE - Execution of step "SET_FMC_MTD_FL_INIT_SLS" failed.

dagster._core.errors.DagsterExecutionStepExecutionError: Error occurred while executing op "SET_FMC_MTD_FL_INIT_SLS"::

snowflake.connector.errors.ProgrammingError: 100038 (22018): Execution error in store procedure SET_FMC_MTD_FL_INIT_SLS:
Numeric value '{load_cycle_id}' is not recognized
At Statement.execute, line 48 position 5

Stack Trace:
  File "/Users/bryanmull/miniforge3/envs/dagsteru/lib/python3.11/site-packages/dagster/_core/execution/plan/utils.py", line 54, in op_execution_error_boundary
    yield
  File "/Users/bryanmull/miniforge3/envs/dagsteru/lib/python3.11/site-packages/dagster/_utils/__init__.py", line 468, in iterate_with_context
    next_output = next(iterator)
                  ^^^^^^^^^^^^^^
  File "/Users/bryanmull/miniforge3/envs/dagsteru/lib/python3.11/site-packages/dagster/_core/execution/plan/compute_generator.py", line 141, in _coerce_op_compute_fn_to_iterator
    result = invoke_compute_fn(
             ^^^^^^^^^^^^^^^^^^
  File "/Users/bryanmull/miniforge3/envs/dagsteru/lib/python3.11/site-packages/dagster/_core/execution/plan/compute_generator.py", line 129, in invoke_compute_fn
    return fn(context, **args_to_pass) if context_arg_provided else fn(**args_to_pass)
           ^^^^^^^^^^^^^^^^^^^^^^^^^^^
  File "/Users/bryanmull/Documents/GitHub/quickstart-snowflake-fix-fast-deploys/quickstart_snowflake/assets/init_sales.py", line 27, in SET_FMC_MTD_FL_INIT_SLS
    cursor.execute(query)
  File "/Users/bryanmull/miniforge3/envs/dagsteru/lib/python3.11/site-packages/snowflake/connector/cursor.py", line 1080, in execute
    Error.errorhandler_wrapper(self.connection, self, error_class, errvalue)
  File "/Users/bryanmull/miniforge3/envs/dagsteru/lib/python3.11/site-packages/snowflake/connector/errors.py", line 290, in errorhandler_wrapper
    handed_over = Error.hand_to_other_handler(
                  ^^^^^^^^^^^^^^^^^^^^^^^^^^^^
  File "/Users/bryanmull/miniforge3/envs/dagsteru/lib/python3.11/site-packages/snowflake/connector/errors.py", line 345, in hand_to_other_handler
    cursor.errorhandler(connection, cursor, error_class, error_value)
  File "/Users/bryanmull/miniforge3/envs/dagsteru/lib/python3.11/site-packages/snowflake/connector/errors.py", line 221, in default_errorhandler
    raise error_class(
[0m
