[32m2024-06-28 09:24:13 -0400[0m - dagster - [34mDEBUG[0m - __ASSET_JOB - 9d59b4fd-2bd6-4ef8-84b0-743983d0dcb5 - 77011 - LOGS_CAPTURED - Started capturing logs in process (pid: 77011).
[32m2024-06-28 09:24:13 -0400[0m - dagster - [34mDEBUG[0m - __ASSET_JOB - 9d59b4fd-2bd6-4ef8-84b0-743983d0dcb5 - 77011 - SET_FMC_MTD_FL_INIT_SLS - STEP_START - Started execution of step "SET_FMC_MTD_FL_INIT_SLS".
[32m2024-06-28 09:24:13 -0400[0m - dagster - [34mINFO[0m - __ASSET_JOB - 9d59b4fd-2bd6-4ef8-84b0-743983d0dcb5 - SET_FMC_MTD_FL_INIT_SLS - Executing query: 
        CALL SPEEDSHOP_PROC.SET_FMC_MTD_FL_INIT_SLS('INIT_SALES', '100', '2024-06-28 09:24:13');
    
[32m2024-06-28 09:24:14 -0400[0m - dagster - [34mERROR[0m - [31m__ASSET_JOB - 9d59b4fd-2bd6-4ef8-84b0-743983d0dcb5 - 77011 - SET_FMC_MTD_FL_INIT_SLS - STEP_FAILURE - Execution of step "SET_FMC_MTD_FL_INIT_SLS" failed.

dagster._core.errors.DagsterExecutionStepExecutionError: Error occurred while executing op "SET_FMC_MTD_FL_INIT_SLS"::

snowflake.connector.errors.ProgrammingError: 002141 (42601): SQL compilation error:
Unknown user-defined function SPEEDSHOP_PROC.SET_FMC_MTD_FL_INIT_SLS

Stack Trace:
  File "/Users/bryanmull/miniforge3/envs/dagsteru/lib/python3.11/site-packages/dagster/_core/execution/plan/utils.py", line 54, in op_execution_error_boundary
    yield
  File "/Users/bryanmull/miniforge3/envs/dagsteru/lib/python3.11/site-packages/dagster/_utils/__init__.py", line 468, in iterate_with_context
    next_output = next(iterator)
                  ^^^^^^^^^^^^^^
  File "/Users/bryanmull/miniforge3/envs/dagsteru/lib/python3.11/site-packages/dagster/_core/execution/plan/compute_generator.py", line 141, in _coerce_op_compute_fn_to_iterator
    result = invoke_compute_fn(
             ^^^^^^^^^^^^^^^^^^
  File "/Users/bryanmull/miniforge3/envs/dagsteru/lib/python3.11/site-packages/dagster/_core/execution/plan/compute_generator.py", line 129, in invoke_compute_fn
    return fn(context, **args_to_pass) if context_arg_provided else fn(**args_to_pass)
           ^^^^^^^^^^^^^^^^^^^^^^^^^^^
  File "/Users/bryanmull/Documents/GitHub/quickstart-snowflake-fix-fast-deploys/quickstart_snowflake/assets/init_sales.py", line 26, in SET_FMC_MTD_FL_INIT_SLS
    cursor.execute(query)
  File "/Users/bryanmull/miniforge3/envs/dagsteru/lib/python3.11/site-packages/snowflake/connector/cursor.py", line 1080, in execute
    Error.errorhandler_wrapper(self.connection, self, error_class, errvalue)
  File "/Users/bryanmull/miniforge3/envs/dagsteru/lib/python3.11/site-packages/snowflake/connector/errors.py", line 290, in errorhandler_wrapper
    handed_over = Error.hand_to_other_handler(
                  ^^^^^^^^^^^^^^^^^^^^^^^^^^^^
  File "/Users/bryanmull/miniforge3/envs/dagsteru/lib/python3.11/site-packages/snowflake/connector/errors.py", line 345, in hand_to_other_handler
    cursor.errorhandler(connection, cursor, error_class, error_value)
  File "/Users/bryanmull/miniforge3/envs/dagsteru/lib/python3.11/site-packages/snowflake/connector/errors.py", line 221, in default_errorhandler
    raise error_class(
[0m
